Workbook
Name 類別清單: '選單設定'!$A$2:$A$50
Name 付款方式清單: '選單設定'!$B$2:$B$50
Name 薪資計入清單: '選單設定'!$E$2:$E$4
Name 收支類型清單: '選單設定'!$C$2:$C$3
Name 是否清單: '選單設定'!$D$2:$D$3

Sheet 月度總覽
A1: 月計記帳本｜動態每日配額
A2: 先輸入黃色欄位 → 登記固定支出與日常收支 → 查看動態配額與每日順向結果
A4: ① 週期與資金設定 | E4: ② 即時計算結果
A5: 週期開始日 | B5: 46231 | C5: 自訂計算週期的第一天 | E5: 週期天數 | F5: =IF(OR(B5="",B6="",B6<B5),0,B6-B5+1) -> 11
A6: 週期結束日 | B6: 46241 | C6: 自訂計算週期的最後一天 | E6: 配額起算日 | F6: =IF(F5=0,"",MAX(B5,MIN(B7,B6))) -> 2026-07-28
A7: 配額計算基準日 | B7: =TODAY() -> 2026-07-28 | C7: 預設今天；可覆寫為任何日期做情境試算 | E7: 剩餘天數（含基準日） | F7: =IF(F5=0,0,MAX(0,B6-F6+1)) -> 11
A8: 自訂發薪日 | B8: 46241 | C8: 輸入完整日期 | E8: 已計入薪資 | F8: =IF(AND(B8>=B5,B8<=B6),IF(B10="全期預先計入",B9,IF(B10="到帳日自動計入",IF(B8<=B7,B9,0),0)),0) -> #VALUE!
A9: 薪資金額 | B9: 22500 | C9: 請勿在收支明細重複登記同一筆薪資 | E9: 其他收入（截至基準日） | F9: =SUMIFS('收支明細'!$E:$E,'收支明細'!$B:$B,"收入",'收支明細'!$A:$A,">="&B5,'收支明細'!$A:$A,"<="&MIN(B7,B6)) -> #VALUE!
A10: 薪資計入方式 | B10: 到帳日自動計入 | C10: 到帳日計入／全期計入／不計入 | E10: 實際支出（截至基準日） | F10: =SUMIFS('收支明細'!$E:$E,'收支明細'!$B:$B,"支出",'收支明細'!$A:$A,">="&B5,'收支明細'!$A:$A,"<="&MIN(B7,B6)) -> #VALUE!
A11: 期初可用餘額 | B11: 10000 | C11: 週期開始時可動用的餘額 | E11: 未付固定支出預留 | F11: =SUMIFS('固定支出'!$C:$C,'固定支出'!$G:$G,"是",'固定支出'!$F:$F,"否",'固定支出'!$D:$D,">="&B5,'固定支出'!$D:$D,"<="&B6) -> #VALUE!
E12: 剩餘可變動資金 | F12: =B11+F8+F9-F10-F11 -> #VALUE!
E13: 動態每天平均配額 | F13: =IF(F7=0,0,MAX(0,F12/F7)) -> #VALUE!
A14: ③ 順向結果摘要
A15: 若由配額起算日起每天花足配額，週期末可變動資金 | E15: =F12-(F13*F7) -> #VALUE!
A16: 尚未到帳且可能在本週期加入的薪資 | E16: =IF(AND(B10="到帳日自動計入",B8>B7,B8<=B6),B9,0) -> #VALUE!
A17: 計入未來薪資後的週期末預測餘額 | E17: =B15+B16 -> #VALUE!
A20: 提示：固定支出尚未付款時會先預留；付款後請在「收支明細」登記支出，並在「固定支出」把已付款改為『是』，避免重複扣減。

Sheet 收支明細
A1: 收支明細｜只填一行一筆
A3: 日期 | B3: 類型 | C3: 類別 | D3: 項目／說明 | E3: 金額 | F3: 付款方式 | G3: 備註

Sheet 固定支出
A1: 固定支出｜設定扣款日期並追蹤付款
A3: 固定支出名稱 | B3: 類別 | C3: 金額 | D3: 本期扣款日期 | E3: 付款方式 | F3: 已付款 | G3: 啟用 | H3: 備註

Sheet 每日順向結果
A1: 每日順向結果｜由自訂起始日至結束日
A2: 藍欄為事件／實績；紫欄為依目前動態配額推演的未來可變動資金（固定支出已在總覽先行預留）。
A4: 日期 | B4: 星期 | C4: 狀態 | D4: 薪資事件 | E4: 其他收入 | F4: 固定支出到期 | G4: 實際支出 | H4: 建議可變支出 | I4: 當日實際淨額 | J4: 順向可變資金
A5: =IF(1<='月度總覽'!$F$5,'月度總覽'!$B$5+1-1,"") -> 2026-07-28 | B5: =IF(A5="","",TEXT(A5,"aaa")) -> aaa | C5: =IF(A5="","",IF(A5<'月度總覽'!$F$6,"已過",IF(A5='月度總覽'!$F$6,"基準日","未來"))) -> 基準日 | D5: =IF(A5="","",IF(A5='月度總覽'!$B$8,'月度總覽'!$B$9,0)) -> 0.00 | E5: =IF(A5="","",SUMIFS('收支明細'!$E:$E,'收支明細'!$B:$B,"收入",'收支明細'!$A:$A,A5)) -> 0.00 | F5: =IF(A5="","",SUMIFS('固定支出'!$C:$C,'固定支出'!$G:$G,"是",'固定支出'!$D:$D,A5)) -> 0.00 | G5: =IF(A5="","",SUMIFS('收支明細'!$E:$E,'收支明細'!$B:$B,"支出",'收支明細'!$A:$A,A5)) -> 0.00 | H5: =IF(OR(A5="",A5<'月度總覽'!$F$6),0,'月度總覽'!$F$13) -> 909.09 | I5: =IF(A5="","",D5+E5-G5) -> 0.00 | J5: =IF(OR(A5="",A5<'月度總覽'!$F$6),"",'月度總覽'!$F$12-SUM($H$5:H5)+IF(AND('月度總覽'!$B$10="到帳日自動計入",'月度總覽'!$B$8>'月度總覽'!$B$7,'月度總覽'!$B$8<=A5),'月度總覽'!$B$9,0)+SUMIFS($E$5:E5,$A$5:A5,">"&'月度總覽'!$B$7)-SUMIFS($G$5:G5,$A$5:A5,">"&'月度總覽'!$B$7)) -> 9,090.91
A6: =IF(2<='月度總覽'!$F$5,'月度總覽'!$B$5+2-1,"") -> 2026-07-29 | B6: =IF(A6="","",TEXT(A6,"aaa")) -> aaa | C6: =IF(A6="","",IF(A6<'月度總覽'!$F$6,"已過",IF(A6='月度總覽'!$F$6,"基準日","未來"))) -> 未來 | D6: =IF(A6="","",IF(A6='月度總覽'!$B$8,'月度總覽'!$B$9,0)) -> 0.00 | E6: =IF(A6="","",SUMIFS('收支明細'!$E:$E,'收支明細'!$B:$B,"收入",'收支明細'!$A:$A,A6)) -> 0.00 | F6: =IF(A6="","",SUMIFS('固定支出'!$C:$C,'固定支出'!$G:$G,"是",'固定支出'!$D:$D,A6)) -> 0.00 | G6: =IF(A6="","",SUMIFS('收支明細'!$E:$E,'收支明細'!$B:$B,"支出",'收支明細'!$A:$A,A6)) -> 0.00 | H6: =IF(OR(A6="",A6<'月度總覽'!$F$6),0,'月度總覽'!$F$13) -> 909.09 | I6: =IF(A6="","",D6+E6-G6) -> 0.00 | J6: =IF(OR(A6="",A6<'月度總覽'!$F$6),"",'月度總覽'!$F$12-SUM($H$5:H6)+IF(AND('月度總覽'!$B$10="到帳日自動計入",'月度總覽'!$B$8>'月度總覽'!$B$7,'月度總覽'!$B$8<=A6),'月度總覽'!$B$9,0)+SUMIFS($E$5:E6,$A$5:A6,">"&'月度總覽'!$B$7)-SUMIFS($G$5:G6,$A$5:A6,">"&'月度總覽'!$B$7)) -> 8,181.82
A7: =IF(3<='月度總覽'!$F$5,'月度總覽'!$B$5+3-1,"") -> 2026-07-30 | B7: =IF(A7="","",TEXT(A7,"aaa")) -> aaa | C7: =IF(A7="","",IF(A7<'月度總覽'!$F$6,"已過",IF(A7='月度總覽'!$F$6,"基準日","未來"))) -> 未來 | D7: =IF(A7="","",IF(A7='月度總覽'!$B$8,'月度總覽'!$B$9,0)) -> 0.00 | E7: =IF(A7="","",SUMIFS('收支明細'!$E:$E,'收支明細'!$B:$B,"收入",'收支明細'!$A:$A,A7)) -> 0.00 | F7: =IF(A7="","",SUMIFS('固定支出'!$C:$C,'固定支出'!$G:$G,"是",'固定支出'!$D:$D,A7)) -> 0.00 | G7: =IF(A7="","",SUMIFS('收支明細'!$E:$E,'收支明細'!$B:$B,"支出",'收支明細'!$A:$A,A7)) -> 0.00 | H7: =IF(OR(A7="",A7<'月度總覽'!$F$6),0,'月度總覽'!$F$13) -> 909.09 | I7: =IF(A7="","",D7+E7-G7) -> 0.00 | J7: =IF(OR(A7="",A7<'月度總覽'!$F$6),"",'月度總覽'!$F$12-SUM($H$5:H7)+IF(AND('月度總覽'!$B$10="到帳日自動計入",'月度總覽'!$B$8>'月度總覽'!$B$7,'月度總覽'!$B$8<=A7),'月度總覽'!$B$9,0)+SUMIFS($E$5:E7,$A$5:A7,">"&'月度總覽'!$B$7)-SUMIFS($G$5:G7,$A$5:A7,">"&'月度總覽'!$B$7)) -> 7,272.73
A8: =IF(4<='月度總覽'!$F$5,'月度總覽'!$B$5+4-1,"") -> 2026-07-31 | B8: =IF(A8="","",TEXT(A8,"aaa")) -> aaa | C8: =IF(A8="","",IF(A8<'月度總覽'!$F$6,"已過",IF(A8='月度總覽'!$F$6,"基準日","未來"))) -> 未來 | D8: =IF(A8="","",IF(A8='月度總覽'!$B$8,'月度總覽'!$B$9,0)) -> 0.00 | E8: =IF(A8="","",SUMIFS('收支明細'!$E:$E,'收支明細'!$B:$B,"收入",'收支明細'!$A:$A,A8)) -> 0.00 | F8: =IF(A8="","",SUMIFS('固定支出'!$C:$C,'固定支出'!$G:$G,"是",'固定支出'!$D:$D,A8)) -> 0.00 | G8: =IF(A8="","",SUMIFS('收支明細'!$E:$E,'收支明細'!$B:$B,"支出",'收支明細'!$A:$A,A8)) -> 0.00 | H8: =IF(OR(A8="",A8<'月度總覽'!$F$6),0,'月度總覽'!$F$13) -> 909.09 | I8: =IF(A8="","",D8+E8-G8) -> 0.00 | J8: =IF(OR(A8="",A8<'月度總覽'!$F$6),"",'月度總覽'!$F$12-SUM($H$5:H8)+IF(AND('月度總覽'!$B$10="到帳日自動計入",'月度總覽'!$B$8>'月度總覽'!$B$7,'月度總覽'!$B$8<=A8),'月度總覽'!$B$9,0)+SUMIFS($E$5:E8,$A$5:A8,">"&'月度總覽'!$B$7)-SUMIFS($G$5:G8,$A$5:A8,">"&'月度總覽'!$B$7)) -> 6,363.64
A9: =IF(5<='月度總覽'!$F$5,'月度總覽'!$B$5+5-1,"") -> 2026-08-01 | B9: =IF(A9="","",TEXT(A9,"aaa")) -> aaa | C9: =IF(A9="","",IF(A9<'月度總覽'!$F$6,"已過",IF(A9='月度總覽'!$F$6,"基準日","未來"))) -> 未來 | D9: =IF(A9="","",IF(A9='月度總覽'!$B$8,'月度總覽'!$B$9,0)) -> 0.00 | E9: =IF(A9="","",SUMIFS('收支明細'!$E:$E,'收支明細'!$B:$B,"收入",'收支明細'!$A:$A,A9)) -> 0.00 | F9: =IF(A9="","",SUMIFS('固定支出'!$C:$C,'固定支出'!$G:$G,"是",'固定支出'!$D:$D,A9)) -> 0.00 | G9: =IF(A9="","",SUMIFS('收支明細'!$E:$E,'收支明細'!$B:$B,"支出",'收支明細'!$A:$A,A9)) -> 0.00 | H9: =IF(OR(A9="",A9<'月度總覽'!$F$6),0,'月度總覽'!$F$13) -> 909.09 | I9: =IF(A9="","",D9+E9-G9) -> 0.00 | J9: =IF(OR(A9="",A9<'月度總覽'!$F$6),"",'月度總覽'!$F$12-SUM($H$5:H9)+IF(AND('月度總覽'!$B$10="到帳日自動計入",'月度總覽'!$B$8>'月度總覽'!$B$7,'月度總覽'!$B$8<=A9),'月度總覽'!$B$9,0)+SUMIFS($E$5:E9,$A$5:A9,">"&'月度總覽'!$B$7)-SUMIFS($G$5:G9,$A$5:A9,">"&'月度總覽'!$B$7)) -> 5,454.55
A10: =IF(6<='月度總覽'!$F$5,'月度總覽'!$B$5+6-1,"") -> 2026-08-02 | B10: =IF(A10="","",TEXT(A10,"aaa")) -> aaa | C10: =IF(A10="","",IF(A10<'月度總覽'!$F$6,"已過",IF(A10='月度總覽'!$F$6,"基準日","未來"))) -> 未來 | D10: =IF(A10="","",IF(A10='月度總覽'!$B$8,'月度總覽'!$B$9,0)) -> 0.00 | E10: =IF(A10="","",SUMIFS('收支明細'!$E:$E,'收支明細'!$B:$B,"收入",'收支明細'!$A:$A,A10)) -> 0.00 | F10: =IF(A10="","",SUMIFS('固定支出'!$C:$C,'固定支出'!$G:$G,"是",'固定支出'!$D:$D,A10)) -> 0.00 | G10: =IF(A10="","",SUMIFS('收支明細'!$E:$E,'收支明細'!$B:$B,"支出",'收支明細'!$A:$A,A10)) -> 0.00 | H10: =IF(OR(A10="",A10<'月度總覽'!$F$6),0,'月度總覽'!$F$13) -> 909.09 | I10: =IF(A10="","",D10+E10-G10) -> 0.00 | J10: =IF(OR(A10="",A10<'月度總覽'!$F$6),"",'月度總覽'!$F$12-SUM($H$5:H10)+IF(AND('月度總覽'!$B$10="到帳日自動計入",'月度總覽'!$B$8>'月度總覽'!$B$7,'月度總覽'!$B$8<=A10),'月度總覽'!$B$9,0)+SUMIFS($E$5:E10,$A$5:A10,">"&'月度總覽'!$B$7)-SUMIFS($G$5:G10,$A$5:A10,">"&'月度總覽'!$B$7)) -> 4,545.45
A11: =IF(7<='月度總覽'!$F$5,'月度總覽'!$B$5+7-1,"") -> 2026-08-03 | B11: =IF(A11="","",TEXT(A11,"aaa")) -> aaa | C11: =IF(A11="","",IF(A11<'月度總覽'!$F$6,"已過",IF(A11='月度總覽'!$F$6,"基準日","未來"))) -> 未來 | D11: =IF(A11="","",IF(A11='月度總覽'!$B$8,'月度總覽'!$B$9,0)) -> 0.00 | E11: =IF(A11="","",SUMIFS('收支明細'!$E:$E,'收支明細'!$B:$B,"收入",'收支明細'!$A:$A,A11)) -> 0.00 | F11: =IF(A11="","",SUMIFS('固定支出'!$C:$C,'固定支出'!$G:$G,"是",'固定支出'!$D:$D,A11)) -> 0.00 | G11: =IF(A11="","",SUMIFS('收支明細'!$E:$E,'收支明細'!$B:$B,"支出",'收支明細'!$A:$A,A11)) -> 0.00 | H11: =IF(OR(A11="",A11<'月度總覽'!$F$6),0,'月度總覽'!$F$13) -> 909.09 | I11: =IF(A11="","",D11+E11-G11) -> 0.00 | J11: =IF(OR(A11="",A11<'月度總覽'!$F$6),"",'月度總覽'!$F$12-SUM($H$5:H11)+IF(AND('月度總覽'!$B$10="到帳日自動計入",'月度總覽'!$B$8>'月度總覽'!$B$7,'月度總覽'!$B$8<=A11),'月度總覽'!$B$9,0)+SUMIFS($E$5:E11,$A$5:A11,">"&'月度總覽'!$B$7)-SUMIFS($G$5:G11,$A$5:A11,">"&'月度總覽'!$B$7)) -> 3,636.36
A12: =IF(8<='月度總覽'!$F$5,'月度總覽'!$B$5+8-1,"") -> 2026-08-04 | B12: =IF(A12="","",TEXT(A12,"aaa")) -> aaa | C12: =IF(A12="","",IF(A12<'月度總覽'!$F$6,"已過",IF(A12='月度總覽'!$F$6,"基準日","未來"))) -> 未來 | D12: =IF(A12="","",IF(A12='月度總覽'!$B$8,'月度總覽'!$B$9,0)) -> 0.00 | E12: =IF(A12="","",SUMIFS('收支明細'!$E:$E,'收支明細'!$B:$B,"收入",'收支明細'!$A:$A,A12)) -> 0.00 | F12: =IF(A12="","",SUMIFS('固定支出'!$C:$C,'固定支出'!$G:$G,"是",'固定支出'!$D:$D,A12)) -> 0.00 | G12: =IF(A12="","",SUMIFS('收支明細'!$E:$E,'收支明細'!$B:$B,"支出",'收支明細'!$A:$A,A12)) -> 0.00 | H12: =IF(OR(A12="",A12<'月度總覽'!$F$6),0,'月度總覽'!$F$13) -> 909.09 | I12: =IF(A12="","",D12+E12-G12) -> 0.00 | J12: =IF(OR(A12="",A12<'月度總覽'!$F$6),"",'月度總覽'!$F$12-SUM($H$5:H12)+IF(AND('月度總覽'!$B$10="到帳日自動計入",'月度總覽'!$B$8>'月度總覽'!$B$7,'月度總覽'!$B$8<=A12),'月度總覽'!$B$9,0)+SUMIFS($E$5:E12,$A$5:A12,">"&'月度總覽'!$B$7)-SUMIFS($G$5:G12,$A$5:A12,">"&'月度總覽'!$B$7)) -> 2,727.27
A13: =IF(9<='月度總覽'!$F$5,'月度總覽'!$B$5+9-1,"") -> 2026-08-05 | B13: =IF(A13="","",TEXT(A13,"aaa")) -> aaa | C13: =IF(A13="","",IF(A13<'月度總覽'!$F$6,"已過",IF(A13='月度總覽'!$F$6,"基準日","未來"))) -> 未來 | D13: =IF(A13="","",IF(A13='月度總覽'!$B$8,'月度總覽'!$B$9,0)) -> 0.00 | E13: =IF(A13="","",SUMIFS('收支明細'!$E:$E,'收支明細'!$B:$B,"收入",'收支明細'!$A:$A,A13)) -> 0.00 | F13: =IF(A13="","",SUMIFS('固定支出'!$C:$C,'固定支出'!$G:$G,"是",'固定支出'!$D:$D,A13)) -> 0.00 | G13: =IF(A13="","",SUMIFS('收支明細'!$E:$E,'收支明細'!$B:$B,"支出",'收支明細'!$A:$A,A13)) -> 0.00 | H13: =IF(OR(A13="",A13<'月度總覽'!$F$6),0,'月度總覽'!$F$13) -> 909.09 | I13: =IF(A13="","",D13+E13-G13) -> 0.00 | J13: =IF(OR(A13="",A13<'月度總覽'!$F$6),"",'月度總覽'!$F$12-SUM($H$5:H13)+IF(AND('月度總覽'!$B$10="到帳日自動計入",'月度總覽'!$B$8>'月度總覽'!$B$7,'月度總覽'!$B$8<=A13),'月度總覽'!$B$9,0)+SUMIFS($E$5:E13,$A$5:A13,">"&'月度總覽'!$B$7)-SUMIFS($G$5:G13,$A$5:A13,">"&'月度總覽'!$B$7)) -> 1,818.18
A14: =IF(10<='月度總覽'!$F$5,'月度總覽'!$B$5+10-1,"") -> 2026-08-06 | B14: =IF(A14="","",TEXT(A14,"aaa")) -> aaa | C14: =IF(A14="","",IF(A14<'月度總覽'!$F$6,"已過",IF(A14='月度總覽'!$F$6,"基準日","未來"))) -> 未來 | D14: =IF(A14="","",IF(A14='月度總覽'!$B$8,'月度總覽'!$B$9,0)) -> 0.00 | E14: =IF(A14="","",SUMIFS('收支明細'!$E:$E,'收支明細'!$B:$B,"收入",'收支明細'!$A:$A,A14)) -> 0.00 | F14: =IF(A14="","",SUMIFS('固定支出'!$C:$C,'固定支出'!$G:$G,"是",'固定支出'!$D:$D,A14)) -> 0.00 | G14: =IF(A14="","",SUMIFS('收支明細'!$E:$E,'收支明細'!$B:$B,"支出",'收支明細'!$A:$A,A14)) -> 0.00 | H14: =IF(OR(A14="",A14<'月度總覽'!$F$6),0,'月度總覽'!$F$13) -> 909.09 | I14: =IF(A14="","",D14+E14-G14) -> 0.00 | J14: =IF(OR(A14="",A14<'月度總覽'!$F$6),"",'月度總覽'!$F$12-SUM($H$5:H14)+IF(AND('月度總覽'!$B$10="到帳日自動計入",'月度總覽'!$B$8>'月度總覽'!$B$7,'月度總覽'!$B$8<=A14),'月度總覽'!$B$9,0)+SUMIFS($E$5:E14,$A$5:A14,">"&'月度總覽'!$B$7)-SUMIFS($G$5:G14,$A$5:A14,">"&'月度總覽'!$B$7)) -> 909.09
A15: =IF(11<='月度總覽'!$F$5,'月度總覽'!$B$5+11-1,"") -> 2026-08-07 | B15: =IF(A15="","",TEXT(A15,"aaa")) -> aaa | C15: =IF(A15="","",IF(A15<'月度總覽'!$F$6,"已過",IF(A15='月度總覽'!$F$6,"基準日","未來"))) -> 未來 | D15: =IF(A15="","",IF(A15='月度總覽'!$B$8,'月度總覽'!$B$9,0)) -> 22,500.00 | E15: =IF(A15="","",SUMIFS('收支明細'!$E:$E,'收支明細'!$B:$B,"收入",'收支明細'!$A:$A,A15)) -> 0.00 | F15: =IF(A15="","",SUMIFS('固定支出'!$C:$C,'固定支出'!$G:$G,"是",'固定支出'!$D:$D,A15)) -> 0.00 | G15: =IF(A15="","",SUMIFS('收支明細'!$E:$E,'收支明細'!$B:$B,"支出",'收支明細'!$A:$A,A15)) -> 0.00 | H15: =IF(OR(A15="",A15<'月度總覽'!$F$6),0,'月度總覽'!$F$13) -> 909.09 | I15: =IF(A15="","",D15+E15-G15) -> 22,500.00 | J15: =IF(OR(A15="",A15<'月度總覽'!$F$6),"",'月度總覽'!$F$12-SUM($H$5:H15)+IF(AND('月度總覽'!$B$10="到帳日自動計入",'月度總覽'!$B$8>'月度總覽'!$B$7,'月度總覽'!$B$8<=A15),'月度總覽'!$B$9,0)+SUMIFS($E$5:E15,$A$5:A15,">"&'月度總覽'!$B$7)-SUMIFS($G$5:G15,$A$5:A15,">"&'月度總覽'!$B$7)) -> 22,500.00
A16: =IF(12<='月度總覽'!$F$5,'月度總覽'!$B$5+12-1,"") | B16: =IF(A16="","",TEXT(A16,"aaa")) | C16: =IF(A16="","",IF(A16<'月度總覽'!$F$6,"已過",IF(A16='月度總覽'!$F$6,"基準日","未來"))) | D16: =IF(A16="","",IF(A16='月度總覽'!$B$8,'月度總覽'!$B$9,0)) | E16: =IF(A16="","",SUMIFS('收支明細'!$E:$E,'收支明細'!$B:$B,"收入",'收支明細'!$A:$A,A16)) | F16: =IF(A16="","",SUMIFS('固定支出'!$C:$C,'固定支出'!$G:$G,"是",'固定支出'!$D:$D,A16)) | G16: =IF(A16="","",SUMIFS('收支明細'!$E:$E,'收支明細'!$B:$B,"支出",'收支明細'!$A:$A,A16)) | H16: =IF(OR(A16="",A16<'月度總覽'!$F$6),0,'月度總覽'!$F$13) -> 0.00 | I16: =IF(A16="","",D16+E16-G16) | J16: =IF(OR(A16="",A16<'月度總覽'!$F$6),"",'月度總覽'!$F$12-SUM($H$5:H16)+IF(AND('月度總覽'!$B$10="到帳日自動計入",'月度總覽'!$B$8>'月度總覽'!$B$7,'月度總覽'!$B$8<=A16),'月度總覽'!$B$9,0)+SUMIFS($E$5:E16,$A$5:A16,">"&'月度總覽'!$B$7)-SUMIFS($G$5:G16,$A$5:A16,">"&'月度總覽'!$B$7))
A17: =IF(13<='月度總覽'!$F$5,'月度總覽'!$B$5+13-1,"") | B17: =IF(A17="","",TEXT(A17,"aaa")) | C17: =IF(A17="","",IF(A17<'月度總覽'!$F$6,"已過",IF(A17='月度總覽'!$F$6,"基準日","未來"))) | D17: =IF(A17="","",IF(A17='月度總覽'!$B$8,'月度總覽'!$B$9,0)) | E17: =IF(A17="","",SUMIFS('收支明細'!$E:$E,'收支明細'!$B:$B,"收入",'收支明細'!$A:$A,A17)) | F17: =IF(A17="","",SUMIFS('固定支出'!$C:$C,'固定支出'!$G:$G,"是",'固定支出'!$D:$D,A17)) | G17: =IF(A17="","",SUMIFS('收支明細'!$E:$E,'收支明細'!$B:$B,"支出",'收支明細'!$A:$A,A17)) | H17: =IF(OR(A17="",A17<'月度總覽'!$F$6),0,'月度總覽'!$F$13) -> 0.00 | I17: =IF(A17="","",D17+E17-G17) | J17: =IF(OR(A17="",A17<'月度總覽'!$F$6),"",'月度總覽'!$F$12-SUM($H$5:H17)+IF(AND('月度總覽'!$B$10="到帳日自動計入",'月度總覽'!$B$8>'月度總覽'!$B$7,'月度總覽'!$B$8<=A17),'月度總覽'!$B$9,0)+SUMIFS($E$5:E17,$A$5:A17,">"&'月度總覽'!$B$7)-SUMIFS($G$5:G17,$A$5:A17,">"&'月度總覽'!$B$7))
A18: =IF(14<='月度總覽'!$F$5,'月度總覽'!$B$5+14-1,"") | B18: =IF(A18="","",TEXT(A18,"aaa")) | C18: =IF(A18="","",IF(A18<'月度總覽'!$F$6,"已過",IF(A18='月度總覽'!$F$6,"基準日","未來"))) | D18: =IF(A18="","",IF(A18='月度總覽'!$B$8,'月度總覽'!$B$9,0)) | E18: =IF(A18="","",SUMIFS('收支明細'!$E:$E,'收支明細'!$B:$B,"收入",'收支明細'!$A:$A,A18)) | F18: =IF(A18="","",SUMIFS('固定支出'!$C:$C,'固定支出'!$G:$G,"是",'固定支出'!$D:$D,A18)) | G18: =IF(A18="","",SUMIFS('收支明細'!$E:$E,'收支明細'!$B:$B,"支出",'收支明細'!$A:$A,A18)) | H18: =IF(OR(A18="",A18<'月度總覽'!$F$6),0,'月度總覽'!$F$13) -> 0.00 | I18: =IF(A18="","",D18+E18-G18) | J18: =IF(OR(A18="",A18<'月度總覽'!$F$6),"",'月度總覽'!$F$12-SUM($H$5:H18)+IF(AND('月度總覽'!$B$10="到帳日自動計入",'月度總覽'!$B$8>'月度總覽'!$B$7,'月度總覽'!$B$8<=A18),'月度總覽'!$B$9,0)+SUMIFS($E$5:E18,$A$5:A18,">"&'月度總覽'!$B$7)-SUMIFS($G$5:G18,$A$5:A18,">"&'月度總覽'!$B$7))
A19: =IF(15<='月度總覽'!$F$5,'月度總覽'!$B$5+15-1,"") | B19: =IF(A19="","",TEXT(A19,"aaa")) | C19: =IF(A19="","",IF(A19<'月度總覽'!$F$6,"已過",IF(A19='月度總覽'!$F$6,"基準日","未來"))) | D19: =IF(A19="","",IF(A19='月度總覽'!$B$8,'月度總覽'!$B$9,0)) | E19: =IF(A19="","",SUMIFS('收支明細'!$E:$E,'收支明細'!$B:$B,"收入",'收支明細'!$A:$A,A19)) | F19: =IF(A19="","",SUMIFS('固定支出'!$C:$C,'固定支出'!$G:$G,"是",'固定支出'!$D:$D,A19)) | G19: =IF(A19="","",SUMIFS('收支明細'!$E:$E,'收支明細'!$B:$B,"支出",'收支明細'!$A:$A,A19)) | H19: =IF(OR(A19="",A19<'月度總覽'!$F$6),0,'月度總覽'!$F$13) -> 0.00 | I19: =IF(A19="","",D19+E19-G19) | J19: =IF(OR(A19="",A19<'月度總覽'!$F$6),"",'月度總覽'!$F$12-SUM($H$5:H19)+IF(AND('月度總覽'!$B$10="到帳日自動計入",'月度總覽'!$B$8>'月度總覽'!$B$7,'月度總覽'!$B$8<=A19),'月度總覽'!$B$9,0)+SUMIFS($E$5:E19,$A$5:A19,">"&'月度總覽'!$B$7)-SUMIFS($G$5:G19,$A$5:A19,">"&'月度總覽'!$B$7))
A20: =IF(16<='月度總覽'!$F$5,'月度總覽'!$B$5+16-1,"") | B20: =IF(A20="","",TEXT(A20,"aaa")) | C20: =IF(A20="","",IF(A20<'月度總覽'!$F$6,"已過",IF(A20='月度總覽'!$F$6,"基準日","未來"))) | D20: =IF(A20="","",IF(A20='月度總覽'!$B$8,'月度總覽'!$B$9,0)) | E20: =IF(A20="","",SUMIFS('收支明細'!$E:$E,'收支明細'!$B:$B,"收入",'收支明細'!$A:$A,A20)) | F20: =IF(A20="","",SUMIFS('固定支出'!$C:$C,'固定支出'!$G:$G,"是",'固定支出'!$D:$D,A20)) | G20: =IF(A20="","",SUMIFS('收支明細'!$E:$E,'收支明細'!$B:$B,"支出",'收支明細'!$A:$A,A20)) | H20: =IF(OR(A20="",A20<'月度總覽'!$F$6),0,'月度總覽'!$F$13) -> 0.00 | I20: =IF(A20="","",D20+E20-G20) | J20: =IF(OR(A20="",A20<'月度總覽'!$F$6),"",'月度總覽'!$F$12-SUM($H$5:H20)+IF(AND('月度總覽'!$B$10="到帳日自動計入",'月度總覽'!$B$8>'月度總覽'!$B$7,'月度總覽'!$B$8<=A20),'月度總覽'!$B$9,0)+SUMIFS($E$5:E20,$A$5:A20,">"&'月度總覽'!$B$7)-SUMIFS($G$5:G20,$A$5:A20,">"&'月度總覽'!$B$7))
A21: =IF(17<='月度總覽'!$F$5,'月度總覽'!$B$5+17-1,"") | B21: =IF(A21="","",TEXT(A21,"aaa")) | C21: =IF(A21="","",IF(A21<'月度總覽'!$F$6,"已過",IF(A21='月度總覽'!$F$6,"基準日","未來"))) | D21: =IF(A21="","",IF(A21='月度總覽'!$B$8,'月度總覽'!$B$9,0)) | E21: =IF(A21="","",SUMIFS('收支明細'!$E:$E,'收支明細'!$B:$B,"收入",'收支明細'!$A:$A,A21)) | F21: =IF(A21="","",SUMIFS('固定支出'!$C:$C,'固定支出'!$G:$G,"是",'固定支出'!$D:$D,A21)) | G21: =IF(A21="","",SUMIFS('收支明細'!$E:$E,'收支明細'!$B:$B,"支出",'收支明細'!$A:$A,A21)) | H21: =IF(OR(A21="",A21<'月度總覽'!$F$6),0,'月度總覽'!$F$13) -> 0.00 | I21: =IF(A21="","",D21+E21-G21) | J21: =IF(OR(A21="",A21<'月度總覽'!$F$6),"",'月度總覽'!$F$12-SUM($H$5:H21)+IF(AND('月度總覽'!$B$10="到帳日自動計入",'月度總覽'!$B$8>'月度總覽'!$B$7,'月度總覽'!$B$8<=A21),'月度總覽'!$B$9,0)+SUMIFS($E$5:E21,$A$5:A21,">"&'月度總覽'!$B$7)-SUMIFS($G$5:G21,$A$5:A21,">"&'月度總覽'!$B$7))
A22: =IF(18<='月度總覽'!$F$5,'月度總覽'!$B$5+18-1,"") | B22: =IF(A22="","",TEXT(A22,"aaa")) | C22: =IF(A22="","",IF(A22<'月度總覽'!$F$6,"已過",IF(A22='月度總覽'!$F$6,"基準日","未來"))) | D22: =IF(A22="","",IF(A22='月度總覽'!$B$8,'月度總覽'!$B$9,0)) | E22: =IF(A22="","",SUMIFS('收支明細'!$E:$E,'收支明細'!$B:$B,"收入",'收支明細'!$A:$A,A22)) | F22: =IF(A22="","",SUMIFS('固定支出'!$C:$C,'固定支出'!$G:$G,"是",'固定支出'!$D:$D,A22)) | G22: =IF(A22="","",SUMIFS('收支明細'!$E:$E,'收支明細'!$B:$B,"支出",'收支明細'!$A:$A,A22)) | H22: =IF(OR(A22="",A22<'月度總覽'!$F$6),0,'月度總覽'!$F$13) -> 0.00 | I22: =IF(A22="","",D22+E22-G22) | J22: =IF(OR(A22="",A22<'月度總覽'!$F$6),"",'月度總覽'!$F$12-SUM($H$5:H22)+IF(AND('月度總覽'!$B$10="到帳日自動計入",'月度總覽'!$B$8>'月度總覽'!$B$7,'月度總覽'!$B$8<=A22),'月度總覽'!$B$9,0)+SUMIFS($E$5:E22,$A$5:A22,">"&'月度總覽'!$B$7)-SUMIFS($G$5:G22,$A$5:A22,">"&'月度總覽'!$B$7))
A23: =IF(19<='月度總覽'!$F$5,'月度總覽'!$B$5+19-1,"") | B23: =IF(A23="","",TEXT(A23,"aaa")) | C23: =IF(A23="","",IF(A23<'月度總覽'!$F$6,"已過",IF(A23='月度總覽'!$F$6,"基準日","未來"))) | D23: =IF(A23="","",IF(A23='月度總覽'!$B$8,'月度總覽'!$B$9,0)) | E23: =IF(A23="","",SUMIFS('收支明細'!$E:$E,'收支明細'!$B:$B,"收入",'收支明細'!$A:$A,A23)) | F23: =IF(A23="","",SUMIFS('固定支出'!$C:$C,'固定支出'!$G:$G,"是",'固定支出'!$D:$D,A23)) | G23: =IF(A23="","",SUMIFS('收支明細'!$E:$E,'收支明細'!$B:$B,"支出",'收支明細'!$A:$A,A23)) | H23: =IF(OR(A23="",A23<'月度總覽'!$F$6),0,'月度總覽'!$F$13) -> 0.00 | I23: =IF(A23="","",D23+E23-G23) | J23: =IF(OR(A23="",A23<'月度總覽'!$F$6),"",'月度總覽'!$F$12-SUM($H$5:H23)+IF(AND('月度總覽'!$B$10="到帳日自動計入",'月度總覽'!$B$8>'月度總覽'!$B$7,'月度總覽'!$B$8<=A23),'月度總覽'!$B$9,0)+SUMIFS($E$5:E23,$A$5:A23,">"&'月度總覽'!$B$7)-SUMIFS($G$5:G23,$A$5:A23,">"&'月度總覽'!$B$7))
A24: =IF(20<='月度總覽'!$F$5,'月度總覽'!$B$5+20-1,"") | B24: =IF(A24="","",TEXT(A24,"aaa")) | C24: =IF(A24="","",IF(A24<'月度總覽'!$F$6,"已過",IF(A24='月度總覽'!$F$6,"基準日","未來"))) | D24: =IF(A24="","",IF(A24='月度總覽'!$B$8,'月度總覽'!$B$9,0)) | E24: =IF(A24="","",SUMIFS('收支明細'!$E:$E,'收支明細'!$B:$B,"收入",'收支明細'!$A:$A,A24)) | F24: =IF(A24="","",SUMIFS('固定支出'!$C:$C,'固定支出'!$G:$G,"是",'固定支出'!$D:$D,A24)) | G24: =IF(A24="","",SUMIFS('收支明細'!$E:$E,'收支明細'!$B:$B,"支出",'收支明細'!$A:$A,A24)) | H24: =IF(OR(A24="",A24<'月度總覽'!$F$6),0,'月度總覽'!$F$13) -> 0.00 | I24: =IF(A24="","",D24+E24-G24) | J24: =IF(OR(A24="",A24<'月度總覽'!$F$6),"",'月度總覽'!$F$12-SUM($H$5:H24)+IF(AND('月度總覽'!$B$10="到帳日自動計入",'月度總覽'!$B$8>'月度總覽'!$B$7,'月度總覽'!$B$8<=A24),'月度總覽'!$B$9,0)+SUMIFS($E$5:E24,$A$5:A24,">"&'月度總覽'!$B$7)-SUMIFS($G$5:G24,$A$5:A24,">"&'月度總覽'!$B$7))
A25: =IF(21<='月度總覽'!$F$5,'月度總覽'!$B$5+21-1,"") | B25: =IF(A25="","",TEXT(A25,"aaa")) | C25: =IF(A25="","",IF(A25<'月度總覽'!$F$6,"已過",IF(A25='月度總覽'!$F$6,"基準日","未來"))) | D25: =IF(A25="","",IF(A25='月度總覽'!$B$8,'月度總覽'!$B$9,0)) | E25: =IF(A25="","",SUMIFS('收支明細'!$E:$E,'收支明細'!$B:$B,"收入",'收支明細'!$A:$A,A25)) | F25: =IF(A25="","",SUMIFS('固定支出'!$C:$C,'固定支出'!$G:$G,"是",'固定支出'!$D:$D,A25)) | G25: =IF(A25="","",SUMIFS('收支明細'!$E:$E,'收支明細'!$B:$B,"支出",'收支明細'!$A:$A,A25)) | H25: =IF(OR(A25="",A25<'月度總覽'!$F$6),0,'月度總覽'!$F$13) -> 0.00 | I25: =IF(A25="","",D25+E25-G25) | J25: =IF(OR(A25="",A25<'月度總覽'!$F$6),"",'月度總覽'!$F$12-SUM($H$5:H25)+IF(AND('月度總覽'!$B$10="到帳日自動計入",'月度總覽'!$B$8>'月度總覽'!$B$7,'月度總覽'!$B$8<=A25),'月度總覽'!$B$9,0)+SUMIFS($E$5:E25,$A$5:A25,">"&'月度總覽'!$B$7)-SUMIFS($G$5:G25,$A$5:A25,">"&'月度總覽'!$B$7))
A26: =IF(22<='月度總覽'!$F$5,'月度總覽'!$B$5+22-1,"") | B26: =IF(A26="","",TEXT(A26,"aaa")) | C26: =IF(A26="","",IF(A26<'月度總覽'!$F$6,"已過",IF(A26='月度總覽'!$F$6,"基準日","未來"))) | D26: =IF(A26="","",IF(A26='月度總覽'!$B$8,'月度總覽'!$B$9,0)) | E26: =IF(A26="","",SUMIFS('收支明細'!$E:$E,'收支明細'!$B:$B,"收入",'收支明細'!$A:$A,A26)) | F26: =IF(A26="","",SUMIFS('固定支出'!$C:$C,'固定支出'!$G:$G,"是",'固定支出'!$D:$D,A26)) | G26: =IF(A26="","",SUMIFS('收支明細'!$E:$E,'收支明細'!$B:$B,"支出",'收支明細'!$A:$A,A26)) | H26: =IF(OR(A26="",A26<'月度總覽'!$F$6),0,'月度總覽'!$F$13) -> 0.00 | I26: =IF(A26="","",D26+E26-G26) | J26: =IF(OR(A26="",A26<'月度總覽'!$F$6),"",'月度總覽'!$F$12-SUM($H$5:H26)+IF(AND('月度總覽'!$B$10="到帳日自動計入",'月度總覽'!$B$8>'月度總覽'!$B$7,'月度總覽'!$B$8<=A26),'月度總覽'!$B$9,0)+SUMIFS($E$5:E26,$A$5:A26,">"&'月度總覽'!$B$7)-SUMIFS($G$5:G26,$A$5:A26,">"&'月度總覽'!$B$7))
A27: =IF(23<='月度總覽'!$F$5,'月度總覽'!$B$5+23-1,"") | B27: =IF(A27="","",TEXT(A27,"aaa")) | C27: =IF(A27="","",IF(A27<'月度總覽'!$F$6,"已過",IF(A27='月度總覽'!$F$6,"基準日","未來"))) | D27: =IF(A27="","",IF(A27='月度總覽'!$B$8,'月度總覽'!$B$9,0)) | E27: =IF(A27="","",SUMIFS('收支明細'!$E:$E,'收支明細'!$B:$B,"收入",'收支明細'!$A:$A,A27)) | F27: =IF(A27="","",SUMIFS('固定支出'!$C:$C,'固定支出'!$G:$G,"是",'固定支出'!$D:$D,A27)) | G27: =IF(A27="","",SUMIFS('收支明細'!$E:$E,'收支明細'!$B:$B,"支出",'收支明細'!$A:$A,A27)) | H27: =IF(OR(A27="",A27<'月度總覽'!$F$6),0,'月度總覽'!$F$13) -> 0.00 | I27: =IF(A27="","",D27+E27-G27) | J27: =IF(OR(A27="",A27<'月度總覽'!$F$6),"",'月度總覽'!$F$12-SUM($H$5:H27)+IF(AND('月度總覽'!$B$10="到帳日自動計入",'月度總覽'!$B$8>'月度總覽'!$B$7,'月度總覽'!$B$8<=A27),'月度總覽'!$B$9,0)+SUMIFS($E$5:E27,$A$5:A27,">"&'月度總覽'!$B$7)-SUMIFS($G$5:G27,$A$5:A27,">"&'月度總覽'!$B$7))
A28: =IF(24<='月度總覽'!$F$5,'月度總覽'!$B$5+24-1,"") | B28: =IF(A28="","",TEXT(A28,"aaa")) | C28: =IF(A28="","",IF(A28<'月度總覽'!$F$6,"已過",IF(A28='月度總覽'!$F$6,"基準日","未來"))) | D28: =IF(A28="","",IF(A28='月度總覽'!$B$8,'月度總覽'!$B$9,0)) | E28: =IF(A28="","",SUMIFS('收支明細'!$E:$E,'收支明細'!$B:$B,"收入",'收支明細'!$A:$A,A28)) | F28: =IF(A28="","",SUMIFS('固定支出'!$C:$C,'固定支出'!$G:$G,"是",'固定支出'!$D:$D,A28)) | G28: =IF(A28="","",SUMIFS('收支明細'!$E:$E,'收支明細'!$B:$B,"支出",'收支明細'!$A:$A,A28)) | H28: =IF(OR(A28="",A28<'月度總覽'!$F$6),0,'月度總覽'!$F$13) -> 0.00 | I28: =IF(A28="","",D28+E28-G28) | J28: =IF(OR(A28="",A28<'月度總覽'!$F$6),"",'月度總覽'!$F$12-SUM($H$5:H28)+IF(AND('月度總覽'!$B$10="到帳日自動計入",'月度總覽'!$B$8>'月度總覽'!$B$7,'月度總覽'!$B$8<=A28),'月度總覽'!$B$9,0)+SUMIFS($E$5:E28,$A$5:A28,">"&'月度總覽'!$B$7)-SUMIFS($G$5:G28,$A$5:A28,">"&'月度總覽'!$B$7))
A29: =IF(25<='月度總覽'!$F$5,'月度總覽'!$B$5+25-1,"") | B29: =IF(A29="","",TEXT(A29,"aaa")) | C29: =IF(A29="","",IF(A29<'月度總覽'!$F$6,"已過",IF(A29='月度總覽'!$F$6,"基準日","未來"))) | D29: =IF(A29="","",IF(A29='月度總覽'!$B$8,'月度總覽'!$B$9,0)) | E29: =IF(A29="","",SUMIFS('收支明細'!$E:$E,'收支明細'!$B:$B,"收入",'收支明細'!$A:$A,A29)) | F29: =IF(A29="","",SUMIFS('固定支出'!$C:$C,'固定支出'!$G:$G,"是",'固定支出'!$D:$D,A29)) | G29: =IF(A29="","",SUMIFS('收支明細'!$E:$E,'收支明細'!$B:$B,"支出",'收支明細'!$A:$A,A29)) | H29: =IF(OR(A29="",A29<'月度總覽'!$F$6),0,'月度總覽'!$F$13) -> 0.00 | I29: =IF(A29="","",D29+E29-G29) | J29: =IF(OR(A29="",A29<'月度總覽'!$F$6),"",'月度總覽'!$F$12-SUM($H$5:H29)+IF(AND('月度總覽'!$B$10="到帳日自動計入",'月度總覽'!$B$8>'月度總覽'!$B$7,'月度總覽'!$B$8<=A29),'月度總覽'!$B$9,0)+SUMIFS($E$5:E29,$A$5:A29,">"&'月度總覽'!$B$7)-SUMIFS($G$5:G29,$A$5:A29,">"&'月度總覽'!$B$7))
A30: =IF(26<='月度總覽'!$F$5,'月度總覽'!$B$5+26-1,"") | B30: =IF(A30="","",TEXT(A30,"aaa")) | C30: =IF(A30="","",IF(A30<'月度總覽'!$F$6,"已過",IF(A30='月度總覽'!$F$6,"基準日","未來"))) | D30: =IF(A30="","",IF(A30='月度總覽'!$B$8,'月度總覽'!$B$9,0)) | E30: =IF(A30="","",SUMIFS('收支明細'!$E:$E,'收支明細'!$B:$B,"收入",'收支明細'!$A:$A,A30)) | F30: =IF(A30="","",SUMIFS('固定支出'!$C:$C,'固定支出'!$G:$G,"是",'固定支出'!$D:$D,A30)) | G30: =IF(A30="","",SUMIFS('收支明細'!$E:$E,'收支明細'!$B:$B,"支出",'收支明細'!$A:$A,A30)) | H30: =IF(OR(A30="",A30<'月度總覽'!$F$6),0,'月度總覽'!$F$13) -> 0.00 | I30: =IF(A30="","",D30+E30-G30) | J30: =IF(OR(A30="",A30<'月度總覽'!$F$6),"",'月度總覽'!$F$12-SUM($H$5:H30)+IF(AND('月度總覽'!$B$10="到帳日自動計入",'月度總覽'!$B$8>'月度總覽'!$B$7,'月度總覽'!$B$8<=A30),'月度總覽'!$B$9,0)+SUMIFS($E$5:E30,$A$5:A30,">"&'月度總覽'!$B$7)-SUMIFS($G$5:G30,$A$5:A30,">"&'月度總覽'!$B$7))
A31: =IF(27<='月度總覽'!$F$5,'月度總覽'!$B$5+27-1,"") | B31: =IF(A31="","",TEXT(A31,"aaa")) | C31: =IF(A31="","",IF(A31<'月度總覽'!$F$6,"已過",IF(A31='月度總覽'!$F$6,"基準日","未來"))) | D31: =IF(A31="","",IF(A31='月度總覽'!$B$8,'月度總覽'!$B$9,0)) | E31: =IF(A31="","",SUMIFS('收支明細'!$E:$E,'收支明細'!$B:$B,"收入",'收支明細'!$A:$A,A31)) | F31: =IF(A31="","",SUMIFS('固定支出'!$C:$C,'固定支出'!$G:$G,"是",'固定支出'!$D:$D,A31)) | G31: =IF(A31="","",SUMIFS('收支明細'!$E:$E,'收支明細'!$B:$B,"支出",'收支明細'!$A:$A,A31)) | H31: =IF(OR(A31="",A31<'月度總覽'!$F$6),0,'月度總覽'!$F$13) -> 0.00 | I31: =IF(A31="","",D31+E31-G31) | J31: =IF(OR(A31="",A31<'月度總覽'!$F$6),"",'月度總覽'!$F$12-SUM($H$5:H31)+IF(AND('月度總覽'!$B$10="到帳日自動計入",'月度總覽'!$B$8>'月度總覽'!$B$7,'月度總覽'!$B$8<=A31),'月度總覽'!$B$9,0)+SUMIFS($E$5:E31,$A$5:A31,">"&'月度總覽'!$B$7)-SUMIFS($G$5:G31,$A$5:A31,">"&'月度總覽'!$B$7))
A32: =IF(28<='月度總覽'!$F$5,'月度總覽'!$B$5+28-1,"") | B32: =IF(A32="","",TEXT(A32,"aaa")) | C32: =IF(A32="","",IF(A32<'月度總覽'!$F$6,"已過",IF(A32='月度總覽'!$F$6,"基準日","未來"))) | D32: =IF(A32="","",IF(A32='月度總覽'!$B$8,'月度總覽'!$B$9,0)) | E32: =IF(A32="","",SUMIFS('收支明細'!$E:$E,'收支明細'!$B:$B,"收入",'收支明細'!$A:$A,A32)) | F32: =IF(A32="","",SUMIFS('固定支出'!$C:$C,'固定支出'!$G:$G,"是",'固定支出'!$D:$D,A32)) | G32: =IF(A32="","",SUMIFS('收支明細'!$E:$E,'收支明細'!$B:$B,"支出",'收支明細'!$A:$A,A32)) | H32: =IF(OR(A32="",A32<'月度總覽'!$F$6),0,'月度總覽'!$F$13) -> 0.00 | I32: =IF(A32="","",D32+E32-G32) | J32: =IF(OR(A32="",A32<'月度總覽'!$F$6),"",'月度總覽'!$F$12-SUM($H$5:H32)+IF(AND('月度總覽'!$B$10="到帳日自動計入",'月度總覽'!$B$8>'月度總覽'!$B$7,'月度總覽'!$B$8<=A32),'月度總覽'!$B$9,0)+SUMIFS($E$5:E32,$A$5:A32,">"&'月度總覽'!$B$7)-SUMIFS($G$5:G32,$A$5:A32,">"&'月度總覽'!$B$7))
A33: =IF(29<='月度總覽'!$F$5,'月度總覽'!$B$5+29-1,"") | B33: =IF(A33="","",TEXT(A33,"aaa")) | C33: =IF(A33="","",IF(A33<'月度總覽'!$F$6,"已過",IF(A33='月度總覽'!$F$6,"基準日","未來"))) | D33: =IF(A33="","",IF(A33='月度總覽'!$B$8,'月度總覽'!$B$9,0)) | E33: =IF(A33="","",SUMIFS('收支明細'!$E:$E,'收支明細'!$B:$B,"收入",'收支明細'!$A:$A,A33)) | F33: =IF(A33="","",SUMIFS('固定支出'!$C:$C,'固定支出'!$G:$G,"是",'固定支出'!$D:$D,A33)) | G33: =IF(A33="","",SUMIFS('收支明細'!$E:$E,'收支明細'!$B:$B,"支出",'收支明細'!$A:$A,A33)) | H33: =IF(OR(A33="",A33<'月度總覽'!$F$6),0,'月度總覽'!$F$13) -> 0.00 | I33: =IF(A33="","",D33+E33-G33) | J33: =IF(OR(A33="",A33<'月度總覽'!$F$6),"",'月度總覽'!$F$12-SUM($H$5:H33)+IF(AND('月度總覽'!$B$10="到帳日自動計入",'月度總覽'!$B$8>'月度總覽'!$B$7,'月度總覽'!$B$8<=A33),'月度總覽'!$B$9,0)+SUMIFS($E$5:E33,$A$5:A33,">"&'月度總覽'!$B$7)-SUMIFS($G$5:G33,$A$5:A33,">"&'月度總覽'!$B$7))
A34: =IF(30<='月度總覽'!$F$5,'月度總覽'!$B$5+30-1,"") | B34: =IF(A34="","",TEXT(A34,"aaa")) | C34: =IF(A34="","",IF(A34<'月度總覽'!$F$6,"已過",IF(A34='月度總覽'!$F$6,"基準日","未來"))) | D34: =IF(A34="","",IF(A34='月度總覽'!$B$8,'月度總覽'!$B$9,0)) | E34: =IF(A34="","",SUMIFS('收支明細'!$E:$E,'收支明細'!$B:$B,"收入",'收支明細'!$A:$A,A34)) | F34: =IF(A34="","",SUMIFS('固定支出'!$C:$C,'固定支出'!$G:$G,"是",'固定支出'!$D:$D,A34)) | G34: =IF(A34="","",SUMIFS('收支明細'!$E:$E,'收支明細'!$B:$B,"支出",'收支明細'!$A:$A,A34)) | H34: =IF(OR(A34="",A34<'月度總覽'!$F$6),0,'月度總覽'!$F$13) -> 0.00 | I34: =IF(A34="","",D34+E34-G34) | J34: =IF(OR(A34="",A34<'月度總覽'!$F$6),"",'月度總覽'!$F$12-SUM($H$5:H34)+IF(AND('月度總覽'!$B$10="到帳日自動計入",'月度總覽'!$B$8>'月度總覽'!$B$7,'月度總覽'!$B$8<=A34),'月度總覽'!$B$9,0)+SUMIFS($E$5:E34,$A$5:A34,">"&'月度總覽'!$B$7)-SUMIFS($G$5:G34,$A$5:A34,">"&'月度總覽'!$B$7))
A35: =IF(31<='月度總覽'!$F$5,'月度總覽'!$B$5+31-1,"") | B35: =IF(A35="","",TEXT(A35,"aaa")) | C35: =IF(A35="","",IF(A35<'月度總覽'!$F$6,"已過",IF(A35='月度總覽'!$F$6,"基準日","未來"))) | D35: =IF(A35="","",IF(A35='月度總覽'!$B$8,'月度總覽'!$B$9,0)) | E35: =IF(A35="","",SUMIFS('收支明細'!$E:$E,'收支明細'!$B:$B,"收入",'收支明細'!$A:$A,A35)) | F35: =IF(A35="","",SUMIFS('固定支出'!$C:$C,'固定支出'!$G:$G,"是",'固定支出'!$D:$D,A35)) | G35: =IF(A35="","",SUMIFS('收支明細'!$E:$E,'收支明細'!$B:$B,"支出",'收支明細'!$A:$A,A35)) | H35: =IF(OR(A35="",A35<'月度總覽'!$F$6),0,'月度總覽'!$F$13) -> 0.00 | I35: =IF(A35="","",D35+E35-G35) | J35: =IF(OR(A35="",A35<'月度總覽'!$F$6),"",'月度總覽'!$F$12-SUM($H$5:H35)+IF(AND('月度總覽'!$B$10="到帳日自動計入",'月度總覽'!$B$8>'月度總覽'!$B$7,'月度總覽'!$B$8<=A35),'月度總覽'!$B$9,0)+SUMIFS($E$5:E35,$A$5:A35,">"&'月度總覽'!$B$7)-SUMIFS($G$5:G35,$A$5:A35,">"&'月度總覽'!$B$7))
A36: =IF(32<='月度總覽'!$F$5,'月度總覽'!$B$5+32-1,"") | B36: =IF(A36="","",TEXT(A36,"aaa")) | C36: =IF(A36="","",IF(A36<'月度總覽'!$F$6,"已過",IF(A36='月度總覽'!$F$6,"基準日","未來"))) | D36: =IF(A36="","",IF(A36='月度總覽'!$B$8,'月度總覽'!$B$9,0)) | E36: =IF(A36="","",SUMIFS('收支明細'!$E:$E,'收支明細'!$B:$B,"收入",'收支明細'!$A:$A,A36)) | F36: =IF(A36="","",SUMIFS('固定支出'!$C:$C,'固定支出'!$G:$G,"是",'固定支出'!$D:$D,A36)) | G36: =IF(A36="","",SUMIFS('收支明細'!$E:$E,'收支明細'!$B:$B,"支出",'收支明細'!$A:$A,A36)) | H36: =IF(OR(A36="",A36<'月度總覽'!$F$6),0,'月度總覽'!$F$13) -> 0.00 | I36: =IF(A36="","",D36+E36-G36) | J36: =IF(OR(A36="",A36<'月度總覽'!$F$6),"",'月度總覽'!$F$12-SUM($H$5:H36)+IF(AND('月度總覽'!$B$10="到帳日自動計入",'月度總覽'!$B$8>'月度總覽'!$B$7,'月度總覽'!$B$8<=A36),'月度總覽'!$B$9,0)+SUMIFS($E$5:E36,$A$5:A36,">"&'月度總覽'!$B$7)-SUMIFS($G$5:G36,$A$5:A36,">"&'月度總覽'!$B$7))
A37: =IF(33<='月度總覽'!$F$5,'月度總覽'!$B$5+33-1,"") | B37: =IF(A37="","",TEXT(A37,"aaa")) | C37: =IF(A37="","",IF(A37<'月度總覽'!$F$6,"已過",IF(A37='月度總覽'!$F$6,"基準日","未來"))) | D37: =IF(A37="","",IF(A37='月度總覽'!$B$8,'月度總覽'!$B$9,0)) | E37: =IF(A37="","",SUMIFS('收支明細'!$E:$E,'收支明細'!$B:$B,"收入",'收支明細'!$A:$A,A37)) | F37: =IF(A37="","",SUMIFS('固定支出'!$C:$C,'固定支出'!$G:$G,"是",'固定支出'!$D:$D,A37)) | G37: =IF(A37="","",SUMIFS('收支明細'!$E:$E,'收支明細'!$B:$B,"支出",'收支明細'!$A:$A,A37)) | H37: =IF(OR(A37="",A37<'月度總覽'!$F$6),0,'月度總覽'!$F$13) -> 0.00 | I37: =IF(A37="","",D37+E37-G37) | J37: =IF(OR(A37="",A37<'月度總覽'!$F$6),"",'月度總覽'!$F$12-SUM($H$5:H37)+IF(AND('月度總覽'!$B$10="到帳日自動計入",'月度總覽'!$B$8>'月度總覽'!$B$7,'月度總覽'!$B$8<=A37),'月度總覽'!$B$9,0)+SUMIFS($E$5:E37,$A$5:A37,">"&'月度總覽'!$B$7)-SUMIFS($G$5:G37,$A$5:A37,">"&'月度總覽'!$B$7))
A38: =IF(34<='月度總覽'!$F$5,'月度總覽'!$B$5+34-1,"") | B38: =IF(A38="","",TEXT(A38,"aaa")) | C38: =IF(A38="","",IF(A38<'月度總覽'!$F$6,"已過",IF(A38='月度總覽'!$F$6,"基準日","未來"))) | D38: =IF(A38="","",IF(A38='月度總覽'!$B$8,'月度總覽'!$B$9,0)) | E38: =IF(A38="","",SUMIFS('收支明細'!$E:$E,'收支明細'!$B:$B,"收入",'收支明細'!$A:$A,A38)) | F38: =IF(A38="","",SUMIFS('固定支出'!$C:$C,'固定支出'!$G:$G,"是",'固定支出'!$D:$D,A38)) | G38: =IF(A38="","",SUMIFS('收支明細'!$E:$E,'收支明細'!$B:$B,"支出",'收支明細'!$A:$A,A38)) | H38: =IF(OR(A38="",A38<'月度總覽'!$F$6),0,'月度總覽'!$F$13) -> 0.00 | I38: =IF(A38="","",D38+E38-G38) | J38: =IF(OR(A38="",A38<'月度總覽'!$F$6),"",'月度總覽'!$F$12-SUM($H$5:H38)+IF(AND('月度總覽'!$B$10="到帳日自動計入",'月度總覽'!$B$8>'月度總覽'!$B$7,'月度總覽'!$B$8<=A38),'月度總覽'!$B$9,0)+SUMIFS($E$5:E38,$A$5:A38,">"&'月度總覽'!$B$7)-SUMIFS($G$5:G38,$A$5:A38,">"&'月度總覽'!$B$7))
A39: =IF(35<='月度總覽'!$F$5,'月度總覽'!$B$5+35-1,"") | B39: =IF(A39="","",TEXT(A39,"aaa")) | C39: =IF(A39="","",IF(A39<'月度總覽'!$F$6,"已過",IF(A39='月度總覽'!$F$6,"基準日","未來"))) | D39: =IF(A39="","",IF(A39='月度總覽'!$B$8,'月度總覽'!$B$9,0)) | E39: =IF(A39="","",SUMIFS('收支明細'!$E:$E,'收支明細'!$B:$B,"收入",'收支明細'!$A:$A,A39)) | F39: =IF(A39="","",SUMIFS('固定支出'!$C:$C,'固定支出'!$G:$G,"是",'固定支出'!$D:$D,A39)) | G39: =IF(A39="","",SUMIFS('收支明細'!$E:$E,'收支明細'!$B:$B,"支出",'收支明細'!$A:$A,A39)) | H39: =IF(OR(A39="",A39<'月度總覽'!$F$6),0,'月度總覽'!$F$13) -> 0.00 | I39: =IF(A39="","",D39+E39-G39) | J39: =IF(OR(A39="",A39<'月度總覽'!$F$6),"",'月度總覽'!$F$12-SUM($H$5:H39)+IF(AND('月度總覽'!$B$10="到帳日自動計入",'月度總覽'!$B$8>'月度總覽'!$B$7,'月度總覽'!$B$8<=A39),'月度總覽'!$B$9,0)+SUMIFS($E$5:E39,$A$5:A39,">"&'月度總覽'!$B$7)-SUMIFS($G$5:G39,$A$5:A39,">"&'月度總覽'!$B$7))
A40: =IF(36<='月度總覽'!$F$5,'月度總覽'!$B$5+36-1,"") | B40: =IF(A40="","",TEXT(A40,"aaa")) | C40: =IF(A40="","",IF(A40<'月度總覽'!$F$6,"已過",IF(A40='月度總覽'!$F$6,"基準日","未來"))) | D40: =IF(A40="","",IF(A40='月度總覽'!$B$8,'月度總覽'!$B$9,0)) | E40: =IF(A40="","",SUMIFS('收支明細'!$E:$E,'收支明細'!$B:$B,"收入",'收支明細'!$A:$A,A40)) | F40: =IF(A40="","",SUMIFS('固定支出'!$C:$C,'固定支出'!$G:$G,"是",'固定支出'!$D:$D,A40)) | G40: =IF(A40="","",SUMIFS('收支明細'!$E:$E,'收支明細'!$B:$B,"支出",'收支明細'!$A:$A,A40)) | H40: =IF(OR(A40="",A40<'月度總覽'!$F$6),0,'月度總覽'!$F$13) -> 0.00 | I40: =IF(A40="","",D40+E40-G40) | J40: =IF(OR(A40="",A40<'月度總覽'!$F$6),"",'月度總覽'!$F$12-SUM($H$5:H40)+IF(AND('月度總覽'!$B$10="到帳日自動計入",'月度總覽'!$B$8>'月度總覽'!$B$7,'月度總覽'!$B$8<=A40),'月度總覽'!$B$9,0)+SUMIFS($E$5:E40,$A$5:A40,">"&'月度總覽'!$B$7)-SUMIFS($G$5:G40,$A$5:A40,">"&'月度總覽'!$B$7))
A41: =IF(37<='月度總覽'!$F$5,'月度總覽'!$B$5+37-1,"") | B41: =IF(A41="","",TEXT(A41,"aaa")) | C41: =IF(A41="","",IF(A41<'月度總覽'!$F$6,"已過",IF(A41='月度總覽'!$F$6,"基準日","未來"))) | D41: =IF(A41="","",IF(A41='月度總覽'!$B$8,'月度總覽'!$B$9,0)) | E41: =IF(A41="","",SUMIFS('收支明細'!$E:$E,'收支明細'!$B:$B,"收入",'收支明細'!$A:$A,A41)) | F41: =IF(A41="","",SUMIFS('固定支出'!$C:$C,'固定支出'!$G:$G,"是",'固定支出'!$D:$D,A41)) | G41: =IF(A41="","",SUMIFS('收支明細'!$E:$E,'收支明細'!$B:$B,"支出",'收支明細'!$A:$A,A41)) | H41: =IF(OR(A41="",A41<'月度總覽'!$F$6),0,'月度總覽'!$F$13) -> 0.00 | I41: =IF(A41="","",D41+E41-G41) | J41: =IF(OR(A41="",A41<'月度總覽'!$F$6),"",'月度總覽'!$F$12-SUM($H$5:H41)+IF(AND('月度總覽'!$B$10="到帳日自動計入",'月度總覽'!$B$8>'月度總覽'!$B$7,'月度總覽'!$B$8<=A41),'月度總覽'!$B$9,0)+SUMIFS($E$5:E41,$A$5:A41,">"&'月度總覽'!$B$7)-SUMIFS($G$5:G41,$A$5:A41,">"&'月度總覽'!$B$7))
...

Sheet 選單設定
A1: 支出／收入類別 | B1: 付款方式 | C1: 收支類型 | D1: 是／否 | E1: 薪資計入方式 | G1: 說明
A2: 餐飲 | B2: 現金 | C2: 支出 | D2: 是 | E2: 到帳日自動計入 | G2: 可直接修改／新增 A、B 欄選項；下拉選單預留至第 50 列。
A3: 交通 | B3: 信用卡 | C3: 收入 | D3: 否 | E3: 全期預先計入 | G3: 請勿刪除 C～E 欄的核心選項，否則公式判斷可能失效。
A4: 居住 | B4: 扣帳卡 | E4: 不計入
A5: 水電煤 | B5: 轉數快
A6: 通訊 | B6: 銀行轉帳
A7: 保險 | B7: 八達通
A8: 醫療 | B8: 自動轉帳
A9: 日用品 | B9: 其他
A10: 娛樂
A11: 教育
A12: 投資
A13: 薪資
A14: 其他收入
A15: 其他支出

Sheet 使用說明
A1: 使用說明｜閉環操作流程
A3: 1. 設定結果邊界 | B3: 在「月度總覽」黃色欄位輸入自訂開始日、結束日、配額基準日、發薪日、薪資、薪資計入方式與期初餘額。
A4: 2. 預留固定支出 | B4: 在「固定支出」輸入本期完整扣款日期、金額；未付款且啟用的項目會先由可變動資金扣除。
A5: 3. 記錄真實收支 | B5: 在「收支明細」逐筆登記。金額一律輸入正數，以『類型』區分收入或支出。薪資由總覽自動處理，勿重複登記。
A6: 4. 完成固定支出閉環 | B6: 付款後：①在收支明細登記該筆支出；②在固定支出把『已付款』改為『是』。如此預留會被實支替代，不會重複扣款。
A7: 5. 查看動態配額 | B7: 總覽以（期初餘額＋已計入薪資＋其他收入－實際支出－未付固定支出）÷剩餘天數，重算每天平均配額。負數時配額顯示 0。
A8: 6. 查看順向結果 | B8: 「每日順向結果」逐日展示薪資、收入、固定支出、實支、建議支出與預測可變資金；基準日以黃色標示。
A9: 7. 自訂下拉選單 | B9: 在「選單設定」修改類別和付款方式。新增項目可放到第 50 列；核心的收支類型、是／否、薪資計入方式不要刪除。
A12: 公式口徑 | B12: 動態每日配額會依配額基準日變化。若選『到帳日自動計入』，未到帳薪資不會提前提高當日配額；到帳後會自動納入。
